{"date":"Fri May 19 2023 20:21:42 GMT+0700 (Western Indonesia Time)","error":{"code":"ERR_UNHANDLED_REJECTION"},"exception":true,"level":"error","message":"uncaughtException: This error originated either by throwing inside of an async function without a catch block, or by rejecting a promise which was not handled with .catch(). The promise rejected with the reason \"Ups\".\nUnhandledPromiseRejection: This error originated either by throwing inside of an async function without a catch block, or by rejecting a promise which was not handled with .catch(). The promise rejected with the reason \"Ups\".","os":{"loadavg":[0,0,0],"uptime":332134.109},"process":{"argv":["C:\\Program Files\\nodejs\\node.exe","D:\\Kuliah (D)\\ProgramToGitHub\\Belajar Node JS - Udemy\\pzn-nodejs\\belajar-nodejs-logging\\src\\logging-rejection.js"],"cwd":"D:\\Kuliah (D)\\ProgramToGitHub\\Belajar Node JS - Udemy\\pzn-nodejs\\belajar-nodejs-logging","execPath":"C:\\Program Files\\nodejs\\node.exe","gid":null,"memoryUsage":{"arrayBuffers":60052,"external":1041639,"heapTotal":15056896,"heapUsed":11041528,"rss":51310592},"pid":7736,"uid":null,"version":"v18.16.0"},"stack":"UnhandledPromiseRejection: This error originated either by throwing inside of an async function without a catch block, or by rejecting a promise which was not handled with .catch(). The promise rejected with the reason \"Ups\".","trace":[]}
{"date":"Fri May 19 2023 20:22:35 GMT+0700 (Western Indonesia Time)","error":{"code":"ERR_UNHANDLED_REJECTION"},"exception":true,"level":"error","message":"uncaughtException: This error originated either by throwing inside of an async function without a catch block, or by rejecting a promise which was not handled with .catch(). The promise rejected with the reason \"Ups\".\nUnhandledPromiseRejection: This error originated either by throwing inside of an async function without a catch block, or by rejecting a promise which was not handled with .catch(). The promise rejected with the reason \"Ups\".","os":{"loadavg":[0,0,0],"uptime":332186.875},"process":{"argv":["C:\\Program Files\\nodejs\\node.exe","D:\\Kuliah (D)\\ProgramToGitHub\\Belajar Node JS - Udemy\\pzn-nodejs\\belajar-nodejs-logging\\src\\logging-rejection.js"],"cwd":"D:\\Kuliah (D)\\ProgramToGitHub\\Belajar Node JS - Udemy\\pzn-nodejs\\belajar-nodejs-logging","execPath":"C:\\Program Files\\nodejs\\node.exe","gid":null,"memoryUsage":{"arrayBuffers":39848,"external":1021435,"heapTotal":15056896,"heapUsed":10985752,"rss":50712576},"pid":10152,"uid":null,"version":"v18.16.0"},"stack":"UnhandledPromiseRejection: This error originated either by throwing inside of an async function without a catch block, or by rejecting a promise which was not handled with .catch(). The promise rejected with the reason \"Ups\".","trace":[]}
{"date":"Fri May 19 2023 20:22:57 GMT+0700 (Western Indonesia Time)","error":"Ups","exception":true,"level":"error","message":"unhandledRejection: Ups\n  No stack trace","os":{"loadavg":[0,0,0],"uptime":332208.875},"process":{"argv":["C:\\Program Files\\nodejs\\node.exe","D:\\Kuliah (D)\\ProgramToGitHub\\Belajar Node JS - Udemy\\pzn-nodejs\\belajar-nodejs-logging\\src\\logging-rejection.js"],"cwd":"D:\\Kuliah (D)\\ProgramToGitHub\\Belajar Node JS - Udemy\\pzn-nodejs\\belajar-nodejs-logging","execPath":"C:\\Program Files\\nodejs\\node.exe","gid":null,"memoryUsage":{"arrayBuffers":60052,"external":1041639,"heapTotal":14794752,"heapUsed":11143312,"rss":50765824},"pid":29228,"uid":null,"version":"v18.16.0"},"trace":[]}
